time:2024-12-05T00:00:46.960+0000  filename:local_task_job_runner.py:123  levelname:INFO  err_message:::group::Pre task execution logs
time:2024-12-05T00:00:46.967+0000  filename:taskinstance.py:2613  levelname:INFO  err_message:Dependencies all met for dep_context=non-requeueable deps ti=<TaskInstance: error_dag.error_task manual__2024-12-05T00:00:45.076568+00:00 [queued]>
time:2024-12-05T00:00:46.971+0000  filename:taskinstance.py:2613  levelname:INFO  err_message:Dependencies all met for dep_context=requeueable deps ti=<TaskInstance: error_dag.error_task manual__2024-12-05T00:00:45.076568+00:00 [queued]>
time:2024-12-05T00:00:46.971+0000  filename:taskinstance.py:2866  levelname:INFO  err_message:Starting attempt 1 of 2
time:2024-12-05T00:00:46.977+0000  filename:taskinstance.py:2889  levelname:INFO  err_message:Executing <Task(PythonOperator): error_task> on 2024-12-05 00:00:45.076568+00:00
time:2024-12-05T00:00:46.979+0000  filename:standard_task_runner.py:72  levelname:INFO  err_message:Started process 1132 to run task
time:2024-12-05T00:00:46.981+0000  filename:standard_task_runner.py:104  levelname:INFO  err_message:Running: ['***', 'tasks', 'run', 'error_dag', 'error_task', 'manual__2024-12-05T00:00:45.076568+00:00', '--job-id', '236', '--raw', '--subdir', 'DAGS_FOLDER/error_dag.py', '--cfg-path', '/tmp/tmpoqxrx7ld']
time:2024-12-05T00:00:46.982+0000  filename:standard_task_runner.py:105  levelname:INFO  err_message:Job 236: Subtask error_task
time:2024-12-05T00:00:47.008+0000  filename:task_command.py:467  levelname:INFO  err_message:Running <TaskInstance: error_dag.error_task manual__2024-12-05T00:00:45.076568+00:00 [running]> on host 88bd5cc03d91
time:2024-12-05T00:00:47.046+0000  filename:taskinstance.py:3132  levelname:INFO  err_message:Exporting env vars: AIRFLOW_CTX_DAG_OWNER='***' AIRFLOW_CTX_DAG_ID='error_dag' AIRFLOW_CTX_TASK_ID='error_task' AIRFLOW_CTX_EXECUTION_DATE='2024-12-05T00:00:45.076568+00:00' AIRFLOW_CTX_TRY_NUMBER='1' AIRFLOW_CTX_DAG_RUN_ID='manual__2024-12-05T00:00:45.076568+00:00'
time:2024-12-05T00:00:47.046+0000  filename:taskinstance.py:731  levelname:INFO  err_message:::endgroup::
time:2024-12-05T00:00:47.062+0000  filename:taskinstance.py:3311  levelname:ERROR  err_message:Task failed with exception
Traceback (most recent call last):
  File "/home/airflow/.local/lib/python3.11/site-packages/airflow/models/taskinstance.py", line 767, in _execute_task
    result = _execute_callable(context=context, **execute_callable_kwargs)
             ^^^^^^^^^^^^^^^^^^^^^^^^^^^^^^^^^^^^^^^^^^^^^^^^^^^^^^^^^^^^^
  File "/home/airflow/.local/lib/python3.11/site-packages/airflow/models/taskinstance.py", line 733, in _execute_callable
    return ExecutionCallableRunner(
           ^^^^^^^^^^^^^^^^^^^^^^^^
  File "/home/airflow/.local/lib/python3.11/site-packages/airflow/utils/operator_helpers.py", line 252, in run
    return self.func(*args, **kwargs)
           ^^^^^^^^^^^^^^^^^^^^^^^^^^
  File "/home/airflow/.local/lib/python3.11/site-packages/airflow/models/baseoperator.py", line 417, in wrapper
    return func(self, *args, **kwargs)
           ^^^^^^^^^^^^^^^^^^^^^^^^^^^
  File "/home/airflow/.local/lib/python3.11/site-packages/airflow/operators/python.py", line 238, in execute
    return_value = self.execute_callable()
                   ^^^^^^^^^^^^^^^^^^^^^^^
  File "/home/airflow/.local/lib/python3.11/site-packages/airflow/operators/python.py", line 256, in execute_callable
    return runner.run(*self.op_args, **self.op_kwargs)
           ^^^^^^^^^^^^^^^^^^^^^^^^^^^^^^^^^^^^^^^^^^^
  File "/home/airflow/.local/lib/python3.11/site-packages/airflow/utils/operator_helpers.py", line 252, in run
    return self.func(*args, **kwargs)
           ^^^^^^^^^^^^^^^^^^^^^^^^^^
  File "/opt/airflow/dags/error_dag.py", line 8, in raise_error
    raise ValueError(
ValueError: This is an intentional error.
Line 1: Something went wrong.
Line 2: Please check the configuration.
Line 3: Ensure all dependencies are installed.
Line 4: Refer to the documentation for more details.
Line 5: Contact support if the issue persists.
time:2024-12-05T00:00:47.069+0000  filename:taskinstance.py:1225  levelname:INFO  err_message:Marking task as UP_FOR_RETRY. dag_id=error_dag, task_id=error_task, run_id=manual__2024-12-05T00:00:45.076568+00:00, execution_date=20241205T000045, start_date=20241205T000046, end_date=20241205T000047
time:2024-12-05T00:00:47.078+0000  filename:taskinstance.py:340  levelname:INFO  err_message:::group::Post task execution logs
time:2024-12-05T00:00:47.078+0000  filename:standard_task_runner.py:124  levelname:ERROR  err_message:Failed to execute job 236 for task error_task (This is an intentional error.
Line 1: Something went wrong.
Line 2: Please check the configuration.
Line 3: Ensure all dependencies are installed.
Line 4: Refer to the documentation for more details.
Line 5: Contact support if the issue persists.; 1132)
Traceback (most recent call last):
  File "/home/airflow/.local/lib/python3.11/site-packages/airflow/task/task_runner/standard_task_runner.py", line 117, in _start_by_fork
    ret = args.func(args, dag=self.dag)
          ^^^^^^^^^^^^^^^^^^^^^^^^^^^^^
  File "/home/airflow/.local/lib/python3.11/site-packages/airflow/cli/cli_config.py", line 49, in command
    return func(*args, **kwargs)
           ^^^^^^^^^^^^^^^^^^^^^
  File "/home/airflow/.local/lib/python3.11/site-packages/airflow/utils/cli.py", line 116, in wrapper
    return f(*args, **kwargs)
           ^^^^^^^^^^^^^^^^^^
  File "/home/airflow/.local/lib/python3.11/site-packages/airflow/cli/commands/task_command.py", line 483, in task_run
    task_return_code = _run_task_by_selected_method(args, _dag, ti)
                       ^^^^^^^^^^^^^^^^^^^^^^^^^^^^^^^^^^^^^^^^^^^^
  File "/home/airflow/.local/lib/python3.11/site-packages/airflow/cli/commands/task_command.py", line 256, in _run_task_by_selected_method
    return _run_raw_task(args, ti)
           ^^^^^^^^^^^^^^^^^^^^^^^
  File "/home/airflow/.local/lib/python3.11/site-packages/airflow/cli/commands/task_command.py", line 341, in _run_raw_task
    return ti._run_raw_task(
           ^^^^^^^^^^^^^^^^^
  File "/home/airflow/.local/lib/python3.11/site-packages/airflow/utils/session.py", line 97, in wrapper
    return func(*args, session=session, **kwargs)
           ^^^^^^^^^^^^^^^^^^^^^^^^^^^^^^^^^^^^^^
  File "/home/airflow/.local/lib/python3.11/site-packages/airflow/models/taskinstance.py", line 3005, in _run_raw_task
    return _run_raw_task(
           ^^^^^^^^^^^^^^
  File "/home/airflow/.local/lib/python3.11/site-packages/airflow/models/taskinstance.py", line 273, in _run_raw_task
    TaskInstance._execute_task_with_callbacks(
  File "/home/airflow/.local/lib/python3.11/site-packages/airflow/models/taskinstance.py", line 3159, in _execute_task_with_callbacks
    result = self._execute_task(context, task_orig)
             ^^^^^^^^^^^^^^^^^^^^^^^^^^^^^^^^^^^^^^
  File "/home/airflow/.local/lib/python3.11/site-packages/airflow/models/taskinstance.py", line 3183, in _execute_task
    return _execute_task(self, context, task_orig)
           ^^^^^^^^^^^^^^^^^^^^^^^^^^^^^^^^^^^^^^^
  File "/home/airflow/.local/lib/python3.11/site-packages/airflow/models/taskinstance.py", line 767, in _execute_task
    result = _execute_callable(context=context, **execute_callable_kwargs)
             ^^^^^^^^^^^^^^^^^^^^^^^^^^^^^^^^^^^^^^^^^^^^^^^^^^^^^^^^^^^^^
  File "/home/airflow/.local/lib/python3.11/site-packages/airflow/models/taskinstance.py", line 733, in _execute_callable
    return ExecutionCallableRunner(
           ^^^^^^^^^^^^^^^^^^^^^^^^
  File "/home/airflow/.local/lib/python3.11/site-packages/airflow/utils/operator_helpers.py", line 252, in run
    return self.func(*args, **kwargs)
           ^^^^^^^^^^^^^^^^^^^^^^^^^^
  File "/home/airflow/.local/lib/python3.11/site-packages/airflow/models/baseoperator.py", line 417, in wrapper
    return func(self, *args, **kwargs)
           ^^^^^^^^^^^^^^^^^^^^^^^^^^^
  File "/home/airflow/.local/lib/python3.11/site-packages/airflow/operators/python.py", line 238, in execute
    return_value = self.execute_callable()
                   ^^^^^^^^^^^^^^^^^^^^^^^
  File "/home/airflow/.local/lib/python3.11/site-packages/airflow/operators/python.py", line 256, in execute_callable
    return runner.run(*self.op_args, **self.op_kwargs)
           ^^^^^^^^^^^^^^^^^^^^^^^^^^^^^^^^^^^^^^^^^^^
  File "/home/airflow/.local/lib/python3.11/site-packages/airflow/utils/operator_helpers.py", line 252, in run
    return self.func(*args, **kwargs)
           ^^^^^^^^^^^^^^^^^^^^^^^^^^
  File "/opt/airflow/dags/error_dag.py", line 8, in raise_error
    raise ValueError(
ValueError: This is an intentional error.
Line 1: Something went wrong.
Line 2: Please check the configuration.
Line 3: Ensure all dependencies are installed.
Line 4: Refer to the documentation for more details.
Line 5: Contact support if the issue persists.
time:2024-12-05T00:00:47.121+0000  filename:local_task_job_runner.py:266  levelname:INFO  err_message:Task exited with return code 1
time:2024-12-05T00:00:47.132+0000  filename:taskinstance.py:3895  levelname:INFO  err_message:0 downstream tasks scheduled from follow-on schedule check
time:2024-12-05T00:00:47.133+0000  filename:local_task_job_runner.py:245  levelname:INFO  err_message:::endgroup::
time:2024-12-05T00:05:47.903+0000  filename:local_task_job_runner.py:123  levelname:INFO  err_message:::group::Pre task execution logs
time:2024-12-05T00:05:47.911+0000  filename:taskinstance.py:2613  levelname:INFO  err_message:Dependencies all met for dep_context=non-requeueable deps ti=<TaskInstance: error_dag.error_task manual__2024-12-05T00:00:45.076568+00:00 [queued]>
time:2024-12-05T00:05:47.916+0000  filename:taskinstance.py:2613  levelname:INFO  err_message:Dependencies all met for dep_context=requeueable deps ti=<TaskInstance: error_dag.error_task manual__2024-12-05T00:00:45.076568+00:00 [queued]>
time:2024-12-05T00:05:47.916+0000  filename:taskinstance.py:2866  levelname:INFO  err_message:Starting attempt 2 of 2
time:2024-12-05T00:05:47.922+0000  filename:taskinstance.py:2889  levelname:INFO  err_message:Executing <Task(PythonOperator): error_task> on 2024-12-05 00:00:45.076568+00:00
time:2024-12-05T00:05:47.924+0000  filename:standard_task_runner.py:72  levelname:INFO  err_message:Started process 4300 to run task
time:2024-12-05T00:05:47.927+0000  filename:standard_task_runner.py:104  levelname:INFO  err_message:Running: ['***', 'tasks', 'run', 'error_dag', 'error_task', 'manual__2024-12-05T00:00:45.076568+00:00', '--job-id', '237', '--raw', '--subdir', 'DAGS_FOLDER/error_dag.py', '--cfg-path', '/tmp/tmpeaka7r6u']
time:2024-12-05T00:05:47.928+0000  filename:standard_task_runner.py:105  levelname:INFO  err_message:Job 237: Subtask error_task
time:2024-12-05T00:05:47.951+0000  filename:task_command.py:467  levelname:INFO  err_message:Running <TaskInstance: error_dag.error_task manual__2024-12-05T00:00:45.076568+00:00 [running]> on host 88bd5cc03d91
time:2024-12-05T00:05:47.981+0000  filename:taskinstance.py:3132  levelname:INFO  err_message:Exporting env vars: AIRFLOW_CTX_DAG_OWNER='***' AIRFLOW_CTX_DAG_ID='error_dag' AIRFLOW_CTX_TASK_ID='error_task' AIRFLOW_CTX_EXECUTION_DATE='2024-12-05T00:00:45.076568+00:00' AIRFLOW_CTX_TRY_NUMBER='2' AIRFLOW_CTX_DAG_RUN_ID='manual__2024-12-05T00:00:45.076568+00:00'
time:2024-12-05T00:05:47.981+0000  filename:taskinstance.py:731  levelname:INFO  err_message:::endgroup::
time:2024-12-05T00:05:47.988+0000  filename:taskinstance.py:3311  levelname:ERROR  err_message:Task failed with exception
Traceback (most recent call last):
  File "/home/airflow/.local/lib/python3.11/site-packages/airflow/models/taskinstance.py", line 767, in _execute_task
    result = _execute_callable(context=context, **execute_callable_kwargs)
             ^^^^^^^^^^^^^^^^^^^^^^^^^^^^^^^^^^^^^^^^^^^^^^^^^^^^^^^^^^^^^
  File "/home/airflow/.local/lib/python3.11/site-packages/airflow/models/taskinstance.py", line 733, in _execute_callable
    return ExecutionCallableRunner(
           ^^^^^^^^^^^^^^^^^^^^^^^^
  File "/home/airflow/.local/lib/python3.11/site-packages/airflow/utils/operator_helpers.py", line 252, in run
    return self.func(*args, **kwargs)
           ^^^^^^^^^^^^^^^^^^^^^^^^^^
  File "/home/airflow/.local/lib/python3.11/site-packages/airflow/models/baseoperator.py", line 417, in wrapper
    return func(self, *args, **kwargs)
           ^^^^^^^^^^^^^^^^^^^^^^^^^^^
  File "/home/airflow/.local/lib/python3.11/site-packages/airflow/operators/python.py", line 238, in execute
    return_value = self.execute_callable()
                   ^^^^^^^^^^^^^^^^^^^^^^^
  File "/home/airflow/.local/lib/python3.11/site-packages/airflow/operators/python.py", line 256, in execute_callable
    return runner.run(*self.op_args, **self.op_kwargs)
           ^^^^^^^^^^^^^^^^^^^^^^^^^^^^^^^^^^^^^^^^^^^
  File "/home/airflow/.local/lib/python3.11/site-packages/airflow/utils/operator_helpers.py", line 252, in run
    return self.func(*args, **kwargs)
           ^^^^^^^^^^^^^^^^^^^^^^^^^^
  File "/opt/airflow/dags/error_dag.py", line 8, in raise_error
    raise ValueError(
ValueError: This is an intentional error.
Line 1: Something went wrong.
Line 2: Please check the configuration.
Line 3: Ensure all dependencies are installed.
Line 4: Refer to the documentation for more details.
Line 5: Contact support if the issue persists.
time:2024-12-05T00:05:47.993+0000  filename:taskinstance.py:1225  levelname:INFO  err_message:Marking task as FAILED. dag_id=error_dag, task_id=error_task, run_id=manual__2024-12-05T00:00:45.076568+00:00, execution_date=20241205T000045, start_date=20241205T000547, end_date=20241205T000547
time:2024-12-05T00:05:47.997+0000  filename:taskinstance.py:340  levelname:INFO  err_message:::group::Post task execution logs
time:2024-12-05T00:05:47.997+0000  filename:standard_task_runner.py:124  levelname:ERROR  err_message:Failed to execute job 237 for task error_task (This is an intentional error.
Line 1: Something went wrong.
Line 2: Please check the configuration.
Line 3: Ensure all dependencies are installed.
Line 4: Refer to the documentation for more details.
Line 5: Contact support if the issue persists.; 4300)
Traceback (most recent call last):
  File "/home/airflow/.local/lib/python3.11/site-packages/airflow/task/task_runner/standard_task_runner.py", line 117, in _start_by_fork
    ret = args.func(args, dag=self.dag)
          ^^^^^^^^^^^^^^^^^^^^^^^^^^^^^
  File "/home/airflow/.local/lib/python3.11/site-packages/airflow/cli/cli_config.py", line 49, in command
    return func(*args, **kwargs)
           ^^^^^^^^^^^^^^^^^^^^^
  File "/home/airflow/.local/lib/python3.11/site-packages/airflow/utils/cli.py", line 116, in wrapper
    return f(*args, **kwargs)
           ^^^^^^^^^^^^^^^^^^
  File "/home/airflow/.local/lib/python3.11/site-packages/airflow/cli/commands/task_command.py", line 483, in task_run
    task_return_code = _run_task_by_selected_method(args, _dag, ti)
                       ^^^^^^^^^^^^^^^^^^^^^^^^^^^^^^^^^^^^^^^^^^^^
  File "/home/airflow/.local/lib/python3.11/site-packages/airflow/cli/commands/task_command.py", line 256, in _run_task_by_selected_method
    return _run_raw_task(args, ti)
           ^^^^^^^^^^^^^^^^^^^^^^^
  File "/home/airflow/.local/lib/python3.11/site-packages/airflow/cli/commands/task_command.py", line 341, in _run_raw_task
    return ti._run_raw_task(
           ^^^^^^^^^^^^^^^^^
  File "/home/airflow/.local/lib/python3.11/site-packages/airflow/utils/session.py", line 97, in wrapper
    return func(*args, session=session, **kwargs)
           ^^^^^^^^^^^^^^^^^^^^^^^^^^^^^^^^^^^^^^
  File "/home/airflow/.local/lib/python3.11/site-packages/airflow/models/taskinstance.py", line 3005, in _run_raw_task
    return _run_raw_task(
           ^^^^^^^^^^^^^^
  File "/home/airflow/.local/lib/python3.11/site-packages/airflow/models/taskinstance.py", line 273, in _run_raw_task
    TaskInstance._execute_task_with_callbacks(
  File "/home/airflow/.local/lib/python3.11/site-packages/airflow/models/taskinstance.py", line 3159, in _execute_task_with_callbacks
    result = self._execute_task(context, task_orig)
             ^^^^^^^^^^^^^^^^^^^^^^^^^^^^^^^^^^^^^^
  File "/home/airflow/.local/lib/python3.11/site-packages/airflow/models/taskinstance.py", line 3183, in _execute_task
    return _execute_task(self, context, task_orig)
           ^^^^^^^^^^^^^^^^^^^^^^^^^^^^^^^^^^^^^^^
  File "/home/airflow/.local/lib/python3.11/site-packages/airflow/models/taskinstance.py", line 767, in _execute_task
    result = _execute_callable(context=context, **execute_callable_kwargs)
             ^^^^^^^^^^^^^^^^^^^^^^^^^^^^^^^^^^^^^^^^^^^^^^^^^^^^^^^^^^^^^
  File "/home/airflow/.local/lib/python3.11/site-packages/airflow/models/taskinstance.py", line 733, in _execute_callable
    return ExecutionCallableRunner(
           ^^^^^^^^^^^^^^^^^^^^^^^^
  File "/home/airflow/.local/lib/python3.11/site-packages/airflow/utils/operator_helpers.py", line 252, in run
    return self.func(*args, **kwargs)
           ^^^^^^^^^^^^^^^^^^^^^^^^^^
  File "/home/airflow/.local/lib/python3.11/site-packages/airflow/models/baseoperator.py", line 417, in wrapper
    return func(self, *args, **kwargs)
           ^^^^^^^^^^^^^^^^^^^^^^^^^^^
  File "/home/airflow/.local/lib/python3.11/site-packages/airflow/operators/python.py", line 238, in execute
    return_value = self.execute_callable()
                   ^^^^^^^^^^^^^^^^^^^^^^^
  File "/home/airflow/.local/lib/python3.11/site-packages/airflow/operators/python.py", line 256, in execute_callable
    return runner.run(*self.op_args, **self.op_kwargs)
           ^^^^^^^^^^^^^^^^^^^^^^^^^^^^^^^^^^^^^^^^^^^
  File "/home/airflow/.local/lib/python3.11/site-packages/airflow/utils/operator_helpers.py", line 252, in run
    return self.func(*args, **kwargs)
           ^^^^^^^^^^^^^^^^^^^^^^^^^^
  File "/opt/airflow/dags/error_dag.py", line 8, in raise_error
    raise ValueError(
ValueError: This is an intentional error.
Line 1: Something went wrong.
Line 2: Please check the configuration.
Line 3: Ensure all dependencies are installed.
Line 4: Refer to the documentation for more details.
Line 5: Contact support if the issue persists.
time:2024-12-05T00:05:48.026+0000  filename:local_task_job_runner.py:266  levelname:INFO  err_message:Task exited with return code 1
time:2024-12-05T00:05:48.036+0000  filename:taskinstance.py:3895  levelname:INFO  err_message:0 downstream tasks scheduled from follow-on schedule check
time:2024-12-05T00:05:48.038+0000  filename:local_task_job_runner.py:245  levelname:INFO  err_message:::endgroup::
